Workbook

Sheet Orders
A1: Order_ID | B1: Order_Date | C1: Customer ID | D1: Product ID | E1: Quantity | F1: Discount Rate | G1: Payment Method | H1: Order Status | I1: Sales Channel | J1: Delivery Days
A2: O000001 | B2: 45949 | C2: C0210 | D2: P1097 | E2: 1 | F2: 0.15 | G2: Wallet | H2: Delivered | I2: Mobile App | J2: 4
A3: O000002 | B3: 45990 | C3: C0028 | D3: P1078 | E3: 4 | F3: 0.2 | G3: Debit Card | H3: Delivered | I3: Marketplace | J3: 3
A4: O000003 | B4: 45811 | C4: C0097 | D4: P1083 | E4: 2 | F4: 0.15 | G4: Cash on Delivery | H4: Delivered | I4: Mobile App | J4: 8
A5: O000004 | B5: 45897 | C5: C0258 | D5: P1047 | E5: 3 | F5: 0.2 | G5: Cash on Delivery | H5: Delivered | I5: Mobile App | J5: 3
A6: O000005 | B6: 45924 | C6: C0119 | D6: P1018 | E6: 1 | F6: 0 | G6: Debit Card | H6: Delivered | I6: Marketplace | J6: 2
A7: O000006 | B7: 45712 | C7: C0164 | D7: P1086 | E7: 4 | F7: 0.1 | G7: Credit Card | H7: Delivered | I7: Marketplace | J7: 1
A8: O000007 | B8: 45667 | C8: C0279 | D8: P1100 | E8: 3 | F8: 0 | G8: Debit Card | H8: Delivered | I8: Website | J8: 1
A9: O000008 | B9: 45701 | C9: C0141 | D9: P1027 | E9: 1 | F9: 0.05 | G9: Credit Card | H9: Delivered | I9: Marketplace | J9: 5
A10: O000009 | B10: 45776 | C10: C0178 | D10: P1026 | E10: 1 | F10: 0.05 | G10: Cash on Delivery | H10: Cancelled | I10: Marketplace
A11: O000010 | B11: 45820 | C11: C0239 | D11: P1029 | E11: 4 | F11: 0 | G11: Credit Card | H11: Delivered | I11: Marketplace | J11: 4
A12: O000011 | B12: 45870 | C12: C0202 | D12: P1052 | E12: 3 | F12: 0 | G12: UPI | H12: Shipped | I12: Marketplace | J12: 7
A13: O000012 | B13: 45740 | C13: C0025 | D13: P1078 | E13: 1 | F13: 0.2 | G13: UPI | H13: Delivered | I13: Website | J13: 7
A14: O000013 | B14: 45837 | C14: C0294 | D14: P1084 | E14: 1 | F14: 0 | G14: UPI | H14: Delivered | I14: Website | J14: 3
A15: Category | B15: Sum - Net Profit | C15: C0187 | D15: P1083 | E15: 1 | F15: 0.1 | G15: Debit Card | H15: Shipped | I15: Mobile App | J15: 8
A16: Appliances | B16: 152944.1 | C16: C0240 | D16: P1053 | E16: 1 | F16: 0 | G16: Debit Card | H16: Delivered | I16: Mobile App | J16: 1
A17: Beauty | B17: 71643.1 | C17: C0176 | D17: P1066 | E17: 1 | F17: 0.05 | G17: UPI | H17: Cancelled | I17: Marketplace
A18: Books & Stationery | B18: 63022.75 | C18: C0220 | D18: P1010 | E18: 3 | F18: 0.15 | G18: Net Banking | H18: Delivered | I18: Website | J18: 5
A19: Electronics | B19: 151043 | C19: C0209 | D19: P1050 | E19: 1 | F19: 0.1 | G19: Debit Card | H19: Delivered | I19: Website | J19: 7
A20: Fashion | B20: 166824.65 | C20: C0146 | D20: P1028 | E20: 2 | F20: 0.2 | G20: Debit Card | H20: Returned | I20: Mobile App | J20: 4
A21: Home & Kitchen | B21: 130803.85 | C21: C0168 | D21: P1040 | E21: 1 | F21: 0.2 | G21: Net Banking | H21: Delivered | I21: Mobile App | J21: 3
A22: Sports & Outdoors | B22: 102658.3 | C22: C0231 | D22: P1019 | E22: 5 | F22: 0.1 | G22: Net Banking | H22: Returned | I22: Mobile App | J22: 2
A23: Total Result | B23: 838939.75 | C23: C0037 | D23: P1050 | E23: 2 | F23: 0 | G23: UPI | H23: Delivered | I23: Mobile App | J23: 8
A24: O000023 | B24: 45661 | C24: C0117 | D24: P1058 | E24: 2 | F24: 0.2 | G24: Credit Card | H24: Delivered | I24: Website | J24: 6
A25: O000024 | B25: 45928 | C25: C0027 | D25: P1026 | E25: 1 | F25: 0.15 | G25: UPI | H25: Processing | I25: Mobile App
A26: O000025 | B26: 45986 | C26: C0027 | D26: P1089 | E26: 1 | F26: 0 | G26: Credit Card | H26: Delivered | I26: Website | J26: 7
A27: O000026 | B27: 45894 | C27: C0076 | D27: P1036 | E27: 1 | F27: 0.2 | G27: Net Banking | H27: Delivered | I27: Website | J27: 6
A28: O000027 | B28: 45752 | C28: C0251 | D28: P1044 | E28: 3 | F28: 0.1 | G28: UPI | H28: Cancelled | I28: Website
A29: O000028 | B29: 45887 | C29: C0124 | D29: P1022 | E29: 2 | F29: 0.25 | G29: Credit Card | H29: Shipped | I29: Mobile App | J29: 1
A30: O000029 | B30: 45693 | C30: C0238 | D30: P1023 | E30: 2 | F30: 0 | G30: Credit Card | H30: Delivered | I30: Mobile App | J30: 8
A31: O000030 | B31: 45892 | C31: C0066 | D31: P1072 | E31: 1 | F31: 0.05 | G31: UPI | H31: Cancelled | I31: Website
A32: O000031 | B32: 45846 | C32: C0033 | D32: P1042 | E32: 1 | F32: 0 | G32: Wallet | H32: Delivered | I32: Mobile App | J32: 1
A33: O000032 | B33: 45704 | C33: C0124 | D33: P1006 | E33: 2 | F33: 0.2 | G33: UPI | H33: Cancelled | I33: Mobile App
A34: O000033 | B34: 45828 | C34: C0057 | D34: P1024 | E34: 1 | F34: 0.05 | G34: UPI | H34: Delivered | I34: Website | J34: 7
A35: O000034 | B35: 45709 | C35: C0157 | D35: P1027 | E35: 4 | F35: 0.1 | G35: Debit Card | H35: Delivered | I35: Website | J35: 8
A36: O000035 | B36: 45866 | C36: C0061 | D36: P1020 | E36: 1 | F36: 0.15 | G36: UPI | H36: Delivered | I36: Mobile App | J36: 4
A37: O000036 | B37: 45663 | C37: C0271 | D37: P1003 | E37: 3 | F37: 0.2 | G37: Credit Card | H37: Delivered | I37: Mobile App | J37: 2
A38: O000037 | B38: 45723 | C38: C0194 | D38: P1047 | E38: 5 | F38: 0.25 | G38: Wallet | H38: Shipped | I38: Mobile App | J38: 8
A39: O000038 | B39: 45947 | C39: C0145 | D39: P1038 | E39: 1 | F39: 0.1 | G39: UPI | H39: Delivered | I39: Marketplace | J39: 1
A40: O000039 | B40: 45846 | C40: C0187 | D40: P1072 | E40: 1 | F40: 0.05 | G40: UPI | H40: Delivered | I40: Marketplace | J40: 6
...

Sheet Products
A1: Product ID | B1: Product Name | C1: Category | D1: Selling Price INR | E1: Unit Cost INR
A2: P1001 | B2: Wireless Earbuds | C2: Electronics | D2: 899 | E2: 499
A3: P1002 | B3: Bluetooth Speaker | C3: Electronics | D3: 1499 | E3: 850
A4: P1003 | B4: Smart Watch | C4: Electronics | D4: 2499 | E4: 1450
A5: P1004 | B5: USB-C Cable | C5: Electronics | D5: 299 | E5: 120
A6: P1005 | B6: Power Bank | C6: Electronics | D6: 1199 | E6: 650
A7: P1006 | B7: Wireless Mouse | C7: Electronics | D7: 699 | E7: 300
A8: P1007 | B8: Keyboard | C8: Electronics | D8: 999 | E8: 480
A9: P1008 | B9: Phone Stand | C9: Electronics | D9: 399 | E9: 150
A10: P1009 | B10: Laptop Sleeve | C10: Electronics | D10: 799 | E10: 350
A11: P1010 | B11: Webcam | C11: Electronics | D11: 1799 | E11: 1050
A12: P1011 | B12: Headphones | C12: Electronics | D12: 1599 | E12: 900
A13: P1012 | B13: Charging Adapter | C13: Electronics | D13: 599 | E13: 260
... A101: P1100 | B101: Coffee Maker | C101: Appliances | D101: 2499 | E101: 1600

Sheet Customers
A1: Customer ID | B1: Customer Name | C1: City | D1: State | E1: Customer Segment
A2: C0001 | B2: Aarav Sharma | C2: Delhi | D2: Delhi | E2: Returning
A3: C0002 | B3: Aanya Nair | C3: Mumbai | D3: Maharashtra | E3: New
A4: C0003 | B4: Aditya Pillai | C4: Bengaluru | D4: Karnataka | E4: Returning
A5: C0004 | B5: Aisha Saxena | C5: Hyderabad | D5: Telangana | E5: Returning
A6: C0005 | B6: Akash Gupta | C6: Chennai | D6: Tamil Nadu | E6: Returning
A7: C0006 | B7: Ananya Das | C7: Kolkata | D7: West Bengal | E7: Returning
A8: C0007 | B8: Arjun Mishra | C8: Pune | D8: Maharashtra | E8: Returning
A9: C0008 | B9: Diya Verma | C9: Jaipur | D9: Rajasthan | E9: New
A10: C0009 | B10: Ishaan Iyer | C10: Ahmedabad | D10: Gujarat | E10: New
A11: C0010 | B11: Kavya Khan | C11: Lucknow | D11: Uttar Pradesh | E11: Returning
A12: C0011 | B12: Krishna Menon | C12: Gurugram | D12: Haryana | E12: New
... A301: C0300 | B301: Yash Mehta | C301: Visakhapatnam | D301: Andhra Pradesh | E301: Returning

Sheet Data Quality
A1: E-Commerce Data Quality Report
A3: Check | B3: Expected Result | C3: Actual Result | D3: Status
A4: Orders Record Count | B4: 1500 | C4: =COUNTA(Orders!A2:A1501) -> 1500 | D4: =IF(C4=B4,"PASS","FAIL") -> PASS
A5: Products Record Count | B5: 100 | C5: =COUNTA(Products!A2:A101) -> 100 | D5: =IF(C5=B5,"PASS","FAIL") -> PASS
A6: Customers Record Count | B6: 300 | C6: =COUNTA(Customers!A2:A301) -> 300 | D6: =IF(C6=B6,"PASS","FAIL") -> PASS
A7: Orders Column Count | B7: 10 | C7: =COUNTA(Orders!A1:J1) -> 10 | D7: =IF(C7=B7,"PASS","FAIL") -> PASS
A8: Products Column Count | B8: 5 | C8: =COUNTA(Products!A1:E1) -> 5 | D8: =IF(C8=B8,"PASS","FAIL") -> PASS
A9: Customers Column Count | B9: 5 | C9: =COUNTA(Customers!A1:E1) -> 5 | D9: =IF(C9=B9,"PASS","FAIL") -> PASS
A10: Duplicate Order IDs | B10: 0 | C10: =COUNTIF(Orders!K2:K1501,"Duplicate") -> 0 | D10: =IF(C10=B10,"PASS","FAIL") -> PASS
A11: Duplicate Product IDs | B11: 0 | C11: =COUNTIF(Products!F2:F101,"Duplicate") -> 0 | D11: =IF(C11=B11,"PASS","FAIL") -> PASS
A12: Duplicate Customer IDs | B12: 0 | C12: =COUNTIF(Customers!F2:F301,"Duplicate") -> 0 | D12: =IF(C12=B12,"PASS","FAIL") -> PASS
A13: Missing Order IDs | B13: 0 | C13: =COUNTBLANK(Orders!A2:A1501) -> 0 | D13: =IF(C13=B13,"PASS","FAIL") -> PASS
A14: Missing Product IDs | B14: 0 | C14: =COUNTBLANK(Products!A2:A101) -> 0 | D14: =IF(C14=B14,"PASS","FAIL") -> PASS
A15: Missing Customer IDs | B15: 0 | C15: =COUNTBLANK(Customers!A2:A301) -> 0 | D15: =IF(C15=B15,"PASS","FAIL") -> PASS
A16: Invalid Customer References | B16: 0 | C16: =SUMPRODUCT(COUNTIF(Customers!A2:A301,Orders!C2:C1501)=0) -> 0 | D16: =IF(C16=B16,"PASS","FAIL") -> PASS
A17: Invalid Product References | B17: 0 | C17: =SUMPRODUCT(COUNTIF(Products!A2:A101,Orders!D2:D1501)=0) -> 0 | D17: =IF(C17=B17,"PASS","FAIL") -> PASS
A18: Invalid Order Dates | B18: 0 | C18: =COUNTIF(Orders!B2:B1501,"<"&DATE(2025,1,1))+COUNTIF(Orders!B2:B1501,">"&DATE(2025,12,31))+COUNTBLANK(Orders!B2:B1501) -> 0 | D18: =IF(C18=B18,"PASS","FAIL") -> PASS
A19: Invalid Quantities | B19: 0 | C19: =COUNTIF(Orders!E2:E1501,"<1")+COUNTIF(Orders!E2:E1501,">5")+COUNTBLANK(Orders!E2:E1501) -> 0 | D19: =IF(C19=B19,"PASS","FAIL") -> PASS
A20: Invalid Discounts | B20: 0 | C20: =COUNTIF(Orders!F2:F1501,"<0")+COUNTIF(Orders!F2:F1501,">0.25")+COUNTBLANK(Orders!F2:F1501) -> 0 | D20: =IF(C20=B20,"PASS","FAIL") -> PASS
A21: Invalid Product Prices | B21: 0 | C21: =COUNTIF(Products!D2:D101,"<=0")+COUNTBLANK(Products!D2:D101) -> 0 | D21: =IF(C21=B21,"PASS","FAIL") -> PASS
A22: Invalid Product Costs | B22: 0 | C22: =COUNTIF(Products!E2:E101,"<=0")+COUNTBLANK(Products!E2:E101) -> 0 | D22: =IF(C22=B22,"PASS","FAIL") -> PASS

Sheet Formula_Analysis
A1: Order ID | B1: Order Date | C1: Customer ID | D1: Product ID | E1: Product Name | F1: Category | G1: Quantity | H1: Selling Price | I1: Unit Cost | J1: Discount Rate | K1: Gross Sales | L1: Discount Amount | M1: Net Revenue | N1: Total Cost | O1: Profit | P1: Profit Margin | Q1: Order Status | R1: Customer City | S1: Customer Segment | T1: Sales Channel | U1: Order Type | V1: Revenue Band | W1: Profit Status | X1: Delivery Category | Y1: Net Profit | AA1: Metric | AB1: Value
A2: =Orders!A2 -> O000001 | B2: =Orders!B2 -> 45949 | C2: =Orders!C2 -> C0210 | D2: =Orders!D2 -> P1097 | E2: =INDEX(Products!$B$2:$B$101,MATCH(D2,Products!$A$2:$A$101,0)) -> Vacuum Cleaner | F2: =INDEX(Products!$C$2:$C$101,MATCH(D2,Products!$A$2:$A$101,0)) -> Appliances | G2: =Orders!E2 -> 1 | H2: =INDEX(Products!$D$2:$D$101,MATCH(D2,Products!$A$2:$A$101,0)) -> 3499 | I2: =INDEX(Products!$E$2:$E$101,MATCH(D2,Products!$A$2:$A$101,0)) -> 2400 | J2: =Orders!F2 -> 0.15 | K2: =G2*H2 -> 3499 | L2: =K2*J2 -> 524.85 | M2: =K2-L2 -> 2974.15 | N2: =G2*I2 -> 2400 | O2: =M2-N2 -> 574.15 | P2: =IFERROR(O2/M2,0) -> 0.19304675 | Q2: =Orders!H2 -> Delivered | R2: =INDEX(Customers!$C$2:$C$301,MATCH(C2,Customers!$A$2:$A$301,0)) -> Lucknow | S2: =INDEX(Customers!$E$2:$E$301,MATCH(C2,Customers!$A$2:$A$301,0)) -> Returning | T2: =Orders!I2 -> Mobile App | U2: =IF(Q2="Delivered","Completed",IF(Q2="Cancelled","Cancelled",IF(Q2="Returned","Returned","In Progress"))) -> Completed | V2: =IF(M2>=10000,"High Value",IF(M2>=5000,"Medium Value","Low Value")) -> Low Value | W2: =IF(O2>0,"Profitable",IF(O2=0,"Break-even","Loss")) -> Profitable | X2: =IF(Q2="Cancelled","Not Applicable",IF(Q2="Processing","Pending",IF(B2="","Unknown",IF(Orders!J2="","Unknown",IF(Orders!J2<=3,"Fast",IF(Orders!J2<=6,"Standard","Slow")))))) -> Standard | Y2: =IF(OR(Q2="Cancelled",Q2="Returned"),0,O2) -> 574.15 | AA2: Total Orders | AB2: =COUNTA(A2:A1501) -> 1500
A3: =Orders!A3 -> O000002 | B3: =Orders!B3 -> 45990 | C3: =Orders!C3 -> C0028 | D3: =Orders!D3 -> P1078 | E3: =INDEX(Products!$B$2:$B$101,MATCH(D3,Products!$A$2:$A$101,0)) -> Sketchbook | F3: =INDEX(Products!$C$2:$C$101,MATCH(D3,Products!$A$2:$A$101,0)) -> Books & Stationery | G3: =Orders!E3 -> 4 | H3: =INDEX(Products!$D$2:$D$101,MATCH(D3,Products!$A$2:$A$101,0)) -> 249 | I3: =INDEX(Products!$E$2:$E$101,MATCH(D3,Products!$A$2:$A$101,0)) -> 90 | J3: =Orders!F3 -> 0.2 | K3: =G3*H3 -> 996 | L3: =K3*J3 -> 199.2 | M3: =K3-L3 -> 796.8 | N3: =G3*I3 -> 360 | O3: =M3-N3 -> 436.8 | P3: =IFERROR(O3/M3,0) -> 0.54819277 | Q3: =Orders!H3 -> Delivered | R3: =INDEX(Customers!$C$2:$C$301,MATCH(C3,Customers!$A$2:$A$301,0)) -> Jaipur | S3: =INDEX(Customers!$E$2:$E$301,MATCH(C3,Customers!$A$2:$A$301,0)) -> VIP | T3: =Orders!I3 -> Marketplace | U3: =IF(Q3="Delivered","Completed",IF(Q3="Cancelled","Cancelled",IF(Q3="Returned","Returned","In Progress"))) -> Completed | V3: =IF(M3>=10000,"High Value",IF(M3>=5000,"Medium Value","Low Value")) -> Low Value | W3: =IF(O3>0,"Profitable",IF(O3=0,"Break-even","Loss")) -> Profitable | X3: =IF(Q3="Cancelled","Not Applicable",IF(Q3="Processing","Pending",IF(B3="","Unknown",IF(Orders!J3="","Unknown",IF(Orders!J3<=3,"Fast",IF(Orders!J3<=6,"Standard","Slow")))))) -> Fast | Y3: =IF(OR(Q3="Cancelled",Q3="Returned"),0,O3) -> 436.8 | AA3: Delivered Orders | AB3: =COUNTIFS(Q2:Q1501,"Delivered") -> 1078
A4: =Orders!A4 -> O000003 | B4: =Orders!B4 -> 45811 | C4: =Orders!C4 -> C0097 | D4: =Orders!D4 -> P1083 | E4: =INDEX(Products!$B$2:$B$101,MATCH(D4,Products!$A$2:$A$101,0)) -> Reading Light | F4: =INDEX(Products!$C$2:$C$101,MATCH(D4,Products!$A$2:$A$101,0)) -> Books & Stationery | G4: =Orders!E4 -> 2 | H4: =INDEX(Products!$D$2:$D$101,MATCH(D4,Products!$A$2:$A$101,0)) -> 399 | I4: =INDEX(Products!$E$2:$E$101,MATCH(D4,Products!$A$2:$A$101,0)) -> 180 | J4: =Orders!F4 -> 0.15 | K4: =G4*H4 -> 798 | L4: =K4*J4 -> 119.7 | M4: =K4-L4 -> 678.3 | N4: =G4*I4 -> 360 | O4: =M4-N4 -> 318.3 | P4: =IFERROR(O4/M4,0) -> 0.46926139 | Q4: =Orders!H4 -> Delivered | R4: =INDEX(Customers!$C$2:$C$301,MATCH(C4,Customers!$A$2:$A$301,0)) -> Surat | S4: =INDEX(Customers!$E$2:$E$301,MATCH(C4,Customers!$A$2:$A$301,0)) -> Returning | T4: =Orders!I4 -> Mobile App | U4: =IF(Q4="Delivered","Completed",IF(Q4="Cancelled","Cancelled",IF(Q4="Returned","Returned","In Progress"))) -> Completed | V4: =IF(M4>=10000,"High Value",IF(M4>=5000,"Medium Value","Low Value")) -> Low Value | W4: =IF(O4>0,"Profitable",IF(O4=0,"Break-even","Loss")) -> Profitable | X4: =IF(Q4="Cancelled","Not Applicable",IF(Q4="Processing","Pending",IF(B4="","Unknown",IF(Orders!J4="","Unknown",IF(Orders!J4<=3,"Fast",IF(Orders!J4<=6,"Standard","Slow")))))) -> Slow | Y4: =IF(OR(Q4="Cancelled",Q4="Returned"),0,O4) -> 318.3 | AA4: Cancelled Orders | AB4: =COUNTIFS(Q2:Q1501,"Cancelled") -> 89
A5: =Orders!A5 -> O000004 | B5: =Orders!B5 -> 45897 | C5: =Orders!C5 -> C0258 | D5: =Orders!D5 -> P1047 | E5: =INDEX(Products!$B$2:$B$101,MATCH(D5,Products!$A$2:$A$101,0)) -> Sunscreen Lotion | F5: =INDEX(Products!$C$2:$C$101,MATCH(D5,Products!$A$2:$A$101,0)) -> Beauty | G5: =Orders!E5 -> 3 | H5: =INDEX(Products!$D$2:$D$101,MATCH(D5,Products!$A$2:$A$101,0)) -> 399 | I5: =INDEX(Products!$E$2:$E$101,MATCH(D5,Products!$A$2:$A$101,0)) -> 170 | J5: =Orders!F5 -> 0.2 | K5: =G5*H5 -> 1197 | L5: =K5*J5 -> 239.4 | M5: =K5-L5 -> 957.6 | N5: =G5*I5 -> 510 | O5: =M5-N5 -> 447.6 | P5: =IFERROR(O5/M5,0) -> 0.46741855 | Q5: =Orders!H5 -> Delivered | R5: =INDEX(Customers!$C$2:$C$301,MATCH(C5,Customers!$A$2:$A$301,0)) -> Nagpur | S5: =INDEX(Customers!$E$2:$E$301,MATCH(C5,Customers!$A$2:$A$301,0)) -> New | T5: =Orders!I5 -> Mobile App | U5: =IF(Q5="Delivered","Completed",IF(Q5="Cancelled","Cancelled",IF(Q5="Returned","Returned","In Progress"))) -> Completed | V5: =IF(M5>=10000,"High Value",IF(M5>=5000,"Medium Value","Low Value")) -> Low Value | W5: =IF(O5>0,"Profitable",IF(O5=0,"Break-even","Loss")) -> Profitable | X5: =IF(Q5="Cancelled","Not Applicable",IF(Q5="Processing","Pending",IF(B5="","Unknown",IF(Orders!J5="","Unknown",IF(Orders!J5<=3,"Fast",IF(Orders!J5<=6,"Standard","Slow")))))) -> Fast | Y5: =IF(OR(Q5="Cancelled",Q5="Returned"),0,O5) -> 447.6 | AA5: Returned Orders | AB5: =COUNTIFS(Q2:Q1501,"Returned") -> 73
A6: =Orders!A6 -> O000005 | B6: =Orders!B6 -> 45924 | C6: =Orders!C6 -> C0119 | D6: =Orders!D6 -> P1018 | E6: =INDEX(Products!$B$2:$B$101,MATCH(D6,Products!$A$2:$A$101,0)) -> Cotton Shirt | F6: =INDEX(Products!$C$2:$C$101,MATCH(D6,Products!$A$2:$A$101,0)) -> Fashion | G6: =Orders!E6 -> 1 | H6: =INDEX(Products!$D$2:$D$101,MATCH(D6,Products!$A$2:$A$101,0)) -> 899 | I6: =INDEX(Products!$E$2:$E$101,MATCH(D6,Products!$A$2:$A$101,0)) -> 420 | J6: =Orders!F6 -> 0 | K6: =G6*H6 -> 899 | L6: =K6*J6 -> 0 | M6: =K6-L6 -> 899 | N6: =G6*I6 -> 420 | O6: =M6-N6 -> 479 | P6: =IFERROR(O6/M6,0) -> 0.53281424 | Q6: =Orders!H6 -> Delivered | R6: =INDEX(Customers!$C$2:$C$301,MATCH(C6,Customers!$A$2:$A$301,0)) -> Coimbatore | S6: =INDEX(Customers!$E$2:$E$301,MATCH(C6,Customers!$A$2:$A$301,0)) -> VIP | T6: =Orders!I6 -> Marketplace | U6: =IF(Q6="Delivered","Completed",IF(Q6="Cancelled","Cancelled",IF(Q6="Returned","Returned","In Progress"))) -> Completed | V6: =IF(M6>=10000,"High Value",IF(M6>=5000,"Medium Value","Low Value")) -> Low Value | W6: =IF(O6>0,"Profitable",IF(O6=0,"Break-even","Loss")) -> Profitable | X6: =IF(Q6="Cancelled","Not Applicable",IF(Q6="Processing","Pending",IF(B6="","Unknown",IF(Orders!J6="","Unknown",IF(Orders!J6<=3,"Fast",IF(Orders!J6<=6,"Standard","Slow")))))) -> Fast | Y6: =IF(OR(Q6="Cancelled",Q6="Returned"),0,O6) -> 479 | AA6: Delivered Revenue | AB6: =SUMIFS(M2:M1501,Q2:Q1501,"Delivered") -> 1682287.2
A7: =Orders!A7 -> O000006 | B7: =Orders!B7 -> 45712 | C7: =Orders!C7 -> C0164 | D7: =Orders!D7 -> P1086 | E7: =INDEX(Products!$B$2:$B$101,MATCH(D7,Products!$A$2:$A$101,0)) -> Geometry Box | F7: =INDEX(Products!$C$2:$C$101,MATCH(D7,Products!$A$2:$A$101,0)) -> Books & Stationery | G7: =Orders!E7 -> 4 | H7: =INDEX(Products!$D$2:$D$101,MATCH(D7,Products!$A$2:$A$101,0)) -> 199 | I7: =INDEX(Products!$E$2:$E$101,MATCH(D7,Products!$A$2:$A$101,0)) -> 70 | J7: =Orders!F7 -> 0.1 | K7: =G7*H7 -> 796 | L7: =K7*J7 -> 79.6 | M7: =K7-L7 -> 716.4 | N7: =G7*I7 -> 280 | O7: =M7-N7 -> 436.4 | P7: =IFERROR(O7/M7,0) -> 0.6091569 | Q7: =Orders!H7 -> Delivered | R7: =INDEX(Customers!$C$2:$C$301,MATCH(C7,Customers!$A$2:$A$301,0)) -> Hyderabad | S7: =INDEX(Customers!$E$2:$E$301,MATCH(C7,Customers!$A$2:$A$301,0)) -> Returning | T7: =Orders!I7 -> Marketplace | U7: =IF(Q7="Delivered","Completed",IF(Q7="Cancelled","Cancelled",IF(Q7="Returned","Returned","In Progress"))) -> Completed | V7: =IF(M7>=10000,"High Value",IF(M7>=5000,"Medium Value","Low Value")) -> Low Value | W7: =IF(O7>0,"Profitable",IF(O7=0,"Break-even","Loss")) -> Profitable | X7: =IF(Q7="Cancelled","Not Applicable",IF(Q7="Processing","Pending",IF(B7="","Unknown",IF(Orders!J7="","Unknown",IF(Orders!J7<=3,"Fast",IF(Orders!J7<=6,"Standard","Slow")))))) -> Fast | Y7: =IF(OR(Q7="Cancelled",Q7="Returned"),0,O7) -> 436.4 | AA7: Delivered Profit | AB7: =SUMIFS(O2:O1501,Q2:Q1501,"Delivered") -> 683645.25
A8: =Orders!A8 -> O000007 | B8: =Orders!B8 -> 45667 | C8: =Orders!C8 -> C0279 | D8: =Orders!D8 -> P1100 | E8: =INDEX(Products!$B$2:$B$101,MATCH(D8,Products!$A$2:$A$101,0)) -> Coffee Maker | F8: =INDEX(Products!$C$2:$C$101,MATCH(D8,Products!$A$2:$A$101,0)) -> Appliances | G8: =Orders!E8 -> 3 | H8: =INDEX(Products!$D$2:$D$101,MATCH(D8,Products!$A$2:$A$101,0)) -> 2499 | I8: =INDEX(Products!$E$2:$E$101,MATCH(D8,Products!$A$2:$A$101,0)) -> 1600 | J8: =Orders!F8 -> 0 | K8: =G8*H8 -> 7497 | L8: =K8*J8 -> 0 | M8: =K8-L8 -> 7497 | N8: =G8*I8 -> 4800 | O8: =M8-N8 -> 2697 | P8: =IFERROR(O8/M8,0) -> 0.3597439 | Q8: =Orders!H8 -> Delivered | R8: =INDEX(Customers!$C$2:$C$301,MATCH(C8,Customers!$A$2:$A$301,0)) -> Coimbatore | S8: =INDEX(Customers!$E$2:$E$301,MATCH(C8,Customers!$A$2:$A$301,0)) -> Returning | T8: =Orders!I8 -> Website | U8: =IF(Q8="Delivered","Completed",IF(Q8="Cancelled","Cancelled",IF(Q8="Returned","Returned","In Progress"))) -> Completed | V8: =IF(M8>=10000,"High Value",IF(M8>=5000,"Medium Value","Low Value")) -> Medium Value | W8: =IF(O8>0,"Profitable",IF(O8=0,"Break-even","Loss")) -> Profitable | X8: =IF(Q8="Cancelled","Not Applicable",IF(Q8="Processing","Pending",IF(B8="","Unknown",IF(Orders!J8="","Unknown",IF(Orders!J8<=3,"Fast",IF(Orders!J8<=6,"Standard","Slow")))))) -> Fast | Y8: =IF(OR(Q8="Cancelled",Q8="Returned"),0,O8) -> 2697 | AA8: Average Delivered Order Revenue | AB8: =AVERAGEIFS(M2:M1501,Q2:Q1501,"Delivered") -> 1560.5633
A9: =Orders!A9 -> O000008 | B9: =Orders!B9 -> 45701 | C9: =Orders!C9 -> C0141 | D9: =Orders!D9 -> P1027 | E9: =INDEX(Products!$B$2:$B$101,MATCH(D9,Products!$A$2:$A$101,0)) -> Belt | F9: =INDEX(Products!$C$2:$C$101,MATCH(D9,Products!$A$2:$A$101,0)) -> Fashion | G9: =Orders!E9 -> 1 | H9: =INDEX(Products!$D$2:$D$101,MATCH(D9,Products!$A$2:$A$101,0)) -> 399 | I9: =INDEX(Products!$E$2:$E$101,MATCH(D9,Products!$A$2:$A$101,0)) -> 160 | J9: =Orders!F9 -> 0.05 | K9: =G9*H9 -> 399 | L9: =K9*J9 -> 19.95 | M9: =K9-L9 -> 379.05 | N9: =G9*I9 -> 160 | O9: =M9-N9 -> 219.05 | P9: =IFERROR(O9/M9,0) -> 0.5778921 | Q9: =Orders!H9 -> Delivered | R9: =INDEX(Customers!$C$2:$C$301,MATCH(C9,Customers!$A$2:$A$301,0)) -> Delhi | S9: =INDEX(Customers!$E$2:$E$301,MATCH(C9,Customers!$A$2:$A$301,0)) -> Returning | T9: =Orders!I9 -> Marketplace | U9: =IF(Q9="Delivered","Completed",IF(Q9="Cancelled","Cancelled",IF(Q9="Returned","Returned","In Progress"))) -> Completed | V9: =IF(M9>=10000,"High Value",IF(M9>=5000,"Medium Value","Low Value")) -> Low Value | W9: =IF(O9>0,"Profitable",IF(O9=0,"Break-even","Loss")) -> Profitable | X9: =IF(Q9="Cancelled","Not Applicable",IF(Q9="Processing","Pending",IF(B9="","Unknown",IF(Orders!J9="","Unknown",IF(Orders!J9<=3,"Fast",IF(Orders!J9<=6,"Standard","Slow")))))) -> Standard | Y9: =IF(OR(Q9="Cancelled",Q9="Returned"),0,O9) -> 219.05 | AA9: High Value Orders | AB9: =COUNTIFS(V2:V1501,"High Value") -> 8
A10: =Orders!A10 -> O000009 | B10: =Orders!B10 -> 45776 | C10: =Orders!C10 -> C0178 | D10: =Orders!D10 -> P1026 | E10: =INDEX(Products!$B$2:$B$101,MATCH(D10,Products!$A$2:$A$101,0)) -> Sunglasses | F10: =INDEX(Products!$C$2:$C$101,MATCH(D10,Products!$A$2:$A$101,0)) -> Fashion | G10: =Orders!E10 -> 1 | H10: =INDEX(Products!$D$2:$D$101,MATCH(D10,Products!$A$2:$A$101,0)) -> 799 | I10: =INDEX(Products!$E$2:$E$101,MATCH(D10,Products!$A$2:$A$101,0)) -> 300 | J10: =Orders!F10 -> 0.05 | K10: =G10*H10 -> 799 | L10: =K10*J10 -> 39.95 | M10: =K10-L10 -> 759.05 | N10: =G10*I10 -> 300 | O10: =M10-N10 -> 459.05 | P10: =IFERROR(O10/M10,0) -> 0.60476912 | Q10: =Orders!H10 -> Cancelled | R10: =INDEX(Customers!$C$2:$C$301,MATCH(C10,Customers!$A$2:$A$301,0)) -> Nagpur | S10: =INDEX(Customers!$E$2:$E$301,MATCH(C10,Customers!$A$2:$A$301,0)) -> VIP | T10: =Orders!I10 -> Marketplace | U10: =IF(Q10="Delivered","Completed",IF(Q10="Cancelled","Cancelled",IF(Q10="Returned","Returned","In Progress"))) -> Cancelled | V10: =IF(M10>=10000,"High Value",IF(M10>=5000,"Medium Value","Low Value")) -> Low Value | W10: =IF(O10>0,"Profitable",IF(O10=0,"Break-even","Loss")) -> Profitable | X10: =IF(Q10="Cancelled","Not Applicable",IF(Q10="Processing","Pending",IF(B10="","Unknown",IF(Orders!J10="","Unknown",IF(Orders!J10<=3,"Fast",IF(Orders!J10<=6,"Standard","Slow")))))) -> Not Applicable | Y10: =IF(OR(Q10="Cancelled",Q10="Returned"),0,O10) -> 0 | AA10: Profitable Orders | AB10: =COUNTIFS(W2:W1501,"Profitable") -> 1500
A11: =Orders!A11 -> O000010 | B11: =Orders!B11 -> 45820 | C11: =Orders!C11 -> C0239 | D11: =Orders!D11 -> P1029 | E11: =INDEX(Products!$B$2:$B$101,MATCH(D11,Products!$A$2:$A$101,0)) -> Scarf | F11: =INDEX(Products!$C$2:$C$101,MATCH(D11,Products!$A$2:$A$101,0)) -> Fashion | G11: =Orders!E11 -> 4 | H11: =INDEX(Products!$D$2:$D$101,MATCH(D11,Products!$A$2:$A$101,0)) -> 299 | I11: =INDEX(Products!$E$2:$E$101,MATCH(D11,Products!$A$2:$A$101,0)) -> 100 | J11: =Orders!F11 -> 0 | K11: =G11*H11 -> 1196 | L11: =K11*J11 -> 0 | M11: =K11-L11 -> 1196 | N11: =G11*I11 -> 400 | O11: =M11-N11 -> 796 | P11: =IFERROR(O11/M11,0) -> 0.66555184 | Q11: =Orders!H11 -> Delivered | R11: =INDEX(Customers!$C$2:$C$301,MATCH(C11,Customers!$A$2:$A$301,0)) -> Coimbatore | S11: =INDEX(Customers!$E$2:$E$301,MATCH(C11,Customers!$A$2:$A$301,0)) -> New | T11: =Orders!I11 -> Marketplace | U11: =IF(Q11="Delivered","Completed",IF(Q11="Cancelled","Cancelled",IF(Q11="Returned","Returned","In Progress"))) -> Completed | V11: =IF(M11>=10000,"High Value",IF(M11>=5000,"Medium Value","Low Value")) -> Low Value | W11: =IF(O11>0,"Profitable",IF(O11=0,"Break-even","Loss")) -> Profitable | X11: =IF(Q11="Cancelled","Not Applicable",IF(Q11="Processing","Pending",IF(B11="","Unknown",IF(Orders!J11="","Unknown",IF(Orders!J11<=3,"Fast",IF(Orders!J11<=6,"Standard","Slow")))))) -> Standard | Y11: =IF(OR(Q11="Cancelled",Q11="Returned"),0,O11) -> 796 | AA11: Average Delivery Days | AB11: =AVERAGEIFS(Orders!J2:J1501,Orders!H2:H1501,"Delivered") -> 4.5686456
A12: =Orders!A12 -> O000011 | B12: =Orders!B12 -> 45870 | C12: =Orders!C12 -> C0202 | D12: =Orders!D12 -> P1052 | E12: =INDEX(Products!$B$2:$B$101,MATCH(D12,Products!$A$2:$A$101,0)) -> Lip Balm Set | F12: =INDEX(Products!$C$2:$C$101,MATCH(D12,Products!$A$2:$A$101,0)) -> Beauty | G12: =Orders!E12 -> 3 | H12: =INDEX(Products!$D$2:$D$101,MATCH(D12,Products!$A$2:$A$101,0)) -> 249 | I12: =INDEX(Products!$E$2:$E$101,MATCH(D12,Products!$A$2:$A$101,0)) -> 90 | J12: =Orders!F12 -> 0 | K12: =G12*H12 -> 747 | L12: =K12*J12 -> 0 | M12: =K12-L12 -> 747 | N12: =G12*I12 -> 270 | O12: =M12-N12 -> 477 | P12: =IFERROR(O12/M12,0) -> 0.63855422 | Q12: =Orders!H12 -> Shipped | R12: =INDEX(Customers!$C$2:$C$301,MATCH(C12,Customers!$A$2:$A$301,0)) -> Mumbai | S12: =INDEX(Customers!$E$2:$E$301,MATCH(C12,Customers!$A$2:$A$301,0)) -> New | T12: =Orders!I12 -> Marketplace | U12: =IF(Q12="Delivered","Completed",IF(Q12="Cancelled","Cancelled",IF(Q12="Returned","Returned","In Progress"))) -> In Progress | V12: =IF(M12>=10000,"High Value",IF(M12>=5000,"Medium Value","Low Value")) -> Low Value | W12: =IF(O12>0,"Profitable",IF(O12=0,"Break-even","Loss")) -> Profitable | X12: =IF(Q12="Cancelled","Not Applicable",IF(Q12="Processing","Pending",IF(B12="","Unknown",IF(Orders!J12="","Unknown",IF(Orders!J12<=3,"Fast",IF(Orders!J12<=6,"Standard","Slow")))))) -> Slow | Y12: =IF(OR(Q12="Cancelled",Q12="Returned"),0,O12) -> 477 | AA12: Fast Deliveries | AB12: =COUNTIFS(X2:X1501,"Fast") -> 485
A13: =Orders!A13 -> O000012 | B13: =Orders!B13 -> 45740 | C13: =Orders!C13 -> C0025 | D13: =Orders!D13 -> P1078 | E13: =INDEX(Products!$B$2:$B$101,MATCH(D13,Products!$A$2:$A$101,0)) -> Sketchbook | F13: =INDEX(Products!$C$2:$C$101,MATCH(D13,Products!$A$2:$A$101,0)) -> Books & Stationery | G13: =Orders!E13 -> 1 | H13: =INDEX(Products!$D$2:$D$101,MATCH(D13,Products!$A$2:$A$101,0)) -> 249 | I13: =INDEX(Products!$E$2:$E$101,MATCH(D13,Products!$A$2:$A$101,0)) -> 90 | J13: =Orders!F13 -> 0.2 | K13: =G13*H13 -> 249 | L13: =K13*J13 -> 49.8 | M13: =K13-L13 -> 199.2 | N13: =G13*I13 -> 90 | O13: =M13-N13 -> 109.2 | P13: =IFERROR(O13/M13,0) -> 0.54819277 | Q13: =Orders!H13 -> Delivered | R13: =INDEX(Customers!$C$2:$C$301,MATCH(C13,Customers!$A$2:$A$301,0)) -> Chennai | S13: =INDEX(Customers!$E$2:$E$301,MATCH(C13,Customers!$A$2:$A$301,0)) -> Returning | T13: =Orders!I13 -> Website | U13: =IF(Q13="Delivered","Completed",IF(Q13="Cancelled","Cancelled",IF(Q13="Returned","Returned","In Progress"))) -> Completed | V13: =IF(M13>=10000,"High Value",IF(M13>=5000,"Medium Value","Low Value")) -> Low Value | W13: =IF(O13>0,"Profitable",IF(O13=0,"Break-even","Loss")) -> Profitable | X13: =IF(Q13="Cancelled","Not Applicable",IF(Q13="Processing","Pending",IF(B13="","Unknown",IF(Orders!J13="","Unknown",IF(Orders!J13<=3,"Fast",IF(Orders!J13<=6,"Standard","Slow")))))) -> Slow | Y13: =IF(OR(Q13="Cancelled",Q13="Returned"),0,O13) -> 109.2
A14: =Orders!A14 -> O000013 | B14: =Orders!B14 -> 45837 | C14: =Orders!C14 -> C0294 | D14: =Orders!D14 -> P1084 | E14: =INDEX(Products!$B$2:$B$101,MATCH(D14,Products!$A$2:$A$101,0)) -> Whiteboard | F14: =INDEX(Products!$C$2:$C$101,MATCH(D14,Products!$A$2:$A$101,0)) -> Books & Stationery | G14: =Orders!E14 -> 1 | H14: =INDEX(Products!$D$2:$D$101,MATCH(D14,Products!$A$2:$A$101,0)) -> 799 | I14: =INDEX(Products!$E$2:$E$101,MATCH(D14,Products!$A$2:$A$101,0)) -> 420 | J14: =Orders!F14 -> 0 | K14: =G14*H14 -> 799 | L14: =K14*J14 -> 0 | M14: =K14-L14 -> 799 | N14: =G14*I14 -> 420 | O14: =M14-N14 -> 379 | P14: =IFERROR(O14/M14,0) -> 0.47434293 | Q14: =Orders!H14 -> Delivered | R14: =INDEX(Customers!$C$2:$C$301,MATCH(C14,Customers!$A$2:$A$301,0)) -> Indore | S14: =INDEX(Customers!$E$2:$E$301,MATCH(C14,Customers!$A$2:$A$301,0)) -> Returning | T14: =Orders!I14 -> Website | U14: =IF(Q14="Delivered","Completed",IF(Q14="Cancelled","Cancelled",IF(Q14="Returned","Returned","In Progress"))) -> Completed | V14: =IF(M14>=10000,"High Value",IF(M14>=5000,"Medium Value","Low Value")) -> Low Value | W14: =IF(O14>0,"Profitable",IF(O14=0,"Break-even","Loss")) -> Profitable | X14: =IF(Q14="Cancelled","Not Applicable",IF(Q14="Processing","Pending",IF(B14="","Unknown",IF(Orders!J14="","Unknown",IF(Orders!J14<=3,"Fast",IF(Orders!J14<=6,"Standard","Slow")))))) -> Fast | Y14: =IF(OR(Q14="Cancelled",Q14="Returned"),0,O14) -> 379
A15: =Orders!A15 -> O000014 | B15: =Orders!B15 -> 45712 | C15: =Orders!C15 -> C0187 | D15: =Orders!D15 -> P1083 | E15: =INDEX(Products!$B$2:$B$101,MATCH(D15,Products!$A$2:$A$101,0)) -> Reading Light | F15: =INDEX(Products!$C$2:$C$101,MATCH(D15,Products!$A$2:$A$101,0)) -> Books & Stationery | G15: =Orders!E15 -> 1 | H15: =INDEX(Products!$D$2:$D$101,MATCH(D15,Products!$A$2:$A$101,0)) -> 399 | I15: =INDEX(Products!$E$2:$E$101,MATCH(D15,Products!$A$2:$A$101,0)) -> 180 | J15: =Orders!F15 -> 0.1 | K15: =G15*H15 -> 399 | L15: =K15*J15 -> 39.9 | M15: =K15-L15 -> 359.1 | N15: =G15*I15 -> 180 | O15: =M15-N15 -> 179.1 | P15: =IFERROR(O15/M15,0) -> 0.49874687 | Q15: =Orders!H15 -> Shipped | R15: =INDEX(Customers!$C$2:$C$301,MATCH(C15,Customers!$A$2:$A$301,0)) -> Pune | S15: =INDEX(Customers!$E$2:$E$301,MATCH(C15,Customers!$A$2:$A$301,0)) -> Returning | T15: =Orders!I15 -> Mobile App | U15: =IF(Q15="Delivered","Completed",IF(Q15="Cancelled","Cancelled",IF(Q15="Returned","Returned","In Progress"))) -> In Progress | V15: =IF(M15>=10000,"High Value",IF(M15>=5000,"Medium Value","Low Value")) -> Low Value | W15: =IF(O15>0,"Profitable",IF(O15=0,"Break-even","Loss")) -> Profitable | X15: =IF(Q15="Cancelled","Not Applicable",IF(Q15="Processing","Pending",IF(B15="","Unknown",IF(Orders!J15="","Unknown",IF(Orders!J15<=3,"Fast",IF(Orders!J15<=6,"Standard","Slow")))))) -> Slow | Y15: =IF(OR(Q15="Cancelled",Q15="Returned"),0,O15) -> 179.1
A16: =Orders!A16 -> O000015 | B16: =Orders!B16 -> 45974 | C16: =Orders!C16 -> C0240 | D16: =Orders!D16 -> P1053 | E16: =INDEX(Products!$B$2:$B$101,MATCH(D16,Products!$A$2:$A$101,0)) -> Makeup Brush Set | F16: =INDEX(Products!$C$2:$C$101,MATCH(D16,Products!$A$2:$A$101,0)) -> Beauty | G16: =Orders!E16 -> 1 | H16: =INDEX(Products!$D$2:$D$101,MATCH(D16,Products!$A$2:$A$101,0)) -> 599 | I16: =INDEX(Products!$E$2:$E$101,MATCH(D16,Products!$A$2:$A$101,0)) -> 250 | J16: =Orders!F16 -> 0 | K16: =G16*H16 -> 599 | L16: =K16*J16 -> 0 | M16: =K16-L16 -> 599 | N16: =G16*I16 -> 250 | O16: =M16-N16 -> 349 | P16: =IFERROR(O16/M16,0) -> 0.58263773 | Q16: =Orders!H16 -> Delivered | R16: =INDEX(Customers!$C$2:$C$301,MATCH(C16,Customers!$A$2:$A$301,0)) -> Visakhapatnam | S16: =INDEX(Customers!$E$2:$E$301,MATCH(C16,Customers!$A$2:$A$301,0)) -> Returning | T16: =Orders!I16 -> Mobile App | U16: =IF(Q16="Delivered","Completed",IF(Q16="Cancelled","Cancelled",IF(Q16="Returned","Returned","In Progress"))) -> Completed | V16: =IF(M16>=10000,"High Value",IF(M16>=5000,"Medium Value","Low Value")) -> Low Value | W16: =IF(O16>0,"Profitable",IF(O16=0,"Break-even","Loss")) -> Profitable | X16: =IF(Q16="Cancelled","Not Applicable",IF(Q16="Processing","Pending",IF(B16="","Unknown",IF(Orders!J16="","Unknown",IF(Orders!J16<=3,"Fast",IF(Orders!J16<=6,"Standard","Slow")))))) -> Fast | Y16: =IF(OR(Q16="Cancelled",Q16="Returned"),0,O16) -> 349
A17: =Orders!A17 -> O000016 | B17: =Orders!B17 -> 45729 | C17: =Orders!C17 -> C0176 | D17: =Orders!D17 -> P1066 | E17: =INDEX(Products!$B$2:$B$101,MATCH(D17,Products!$A$2:$A$101,0)) -> Gym Gloves | F17: =INDEX(Products!$C$2:$C$101,MATCH(D17,Products!$A$2:$A$101,0)) -> Sports & Outdoors | G17: =Orders!E17 -> 1 | H17: =INDEX(Products!$D$2:$D$101,MATCH(D17,Products!$A$2:$A$101,0)) -> 499 | I17: =INDEX(Products!$E$2:$E$101,MATCH(D17,Products!$A$2:$A$101,0)) -> 200 | J17: =Orders!F17 -> 0.05 | K17: =G17*H17 -> 499 | L17: =K17*J17 -> 24.95 | M17: =K17-L17 -> 474.05 | N17: =G17*I17 -> 200 | O17: =M17-N17 -> 274.05 | P17: =IFERROR(O17/M17,0) -> 0.57810358 | Q17: =Orders!H17 -> Cancelled | R17: =INDEX(Customers!$C$2:$C$301,MATCH(C17,Customers!$A$2:$A$301,0)) -> Chandigarh | S17: =INDEX(Customers!$E$2:$E$301,MATCH(C17,Customers!$A$2:$A$301,0)) -> New | T17: =Orders!I17 -> Marketplace | U17: =IF(Q17="Delivered","Completed",IF(Q17="Cancelled","Cancelled",IF(Q17="Returned","Returned","In Progress"))) -> Cancelled | V17: =IF(M17>=10000,"High Value",IF(M17>=5000,"Medium Value","Low Value")) -> Low Value | W17: =IF(O17>0,"Profitable",IF(O17=0,"Break-even","Loss")) -> Profitable | X17: =IF(Q17="Cancelled","Not Applicable",IF(Q17="Processing","Pending",IF(B17="","Unknown",IF(Orders!J17="","Unknown",IF(Orders!J17<=3,"Fast",IF(Orders!J17<=6,"Standard","Slow")))))) -> Not Applicable | Y17: =IF(OR(Q17="Cancelled",Q17="Returned"),0,O17) -> 0
A18: =Orders!A18 -> O000017 | B18: =Orders!B18 -> 45849 | C18: =Orders!C18 -> C0220 | D18: =Orders!D18 -> P1010 | E18: =INDEX(Products!$B$2:$B$101,MATCH(D18,Products!$A$2:$A$101,0)) -> Webcam | F18: =INDEX(Products!$C$2:$C$101,MATCH(D18,Products!$A$2:$A$101,0)) -> Electronics | G18: =Orders!E18 -> 3 | H18: =INDEX(Products!$D$2:$D$101,MATCH(D18,Products!$A$2:$A$101,0)) -> 1799 | I18: =INDEX(Products!$E$2:$E$101,MATCH(D18,Products!$A$2:$A$101,0)) -> 1050 | J18: =Orders!F18 -> 0.15 | K18: =G18*H18 -> 5397 | L18: =K18*J18 -> 809.55 | M18: =K18-L18 -> 4587.45 | N18: =G18*I18 -> 3150 | O18: =M18-N18 -> 1437.45 | P18: =IFERROR(O18/M18,0) -> 0.31334401 | Q18: =Orders!H18 -> Delivered | R18: =INDEX(Customers!$C$2:$C$301,MATCH(C18,Customers!$A$2:$A$301,0)) -> Visakhapatnam | S18: =INDEX(Customers!$E$2:$E$301,MATCH(C18,Customers!$A$2:$A$301,0)) -> New | T18: =Orders!I18 -> Website | U18: =IF(Q18="Delivered","Completed",IF(Q18="Cancelled","Cancelled",IF(Q18="Returned","Returned","In Progress"))) -> Completed | V18: =IF(M18>=10000,"High Value",IF(M18>=5000,"Medium Value","Low Value")) -> Low Value | W18: =IF(O18>0,"Profitable",IF(O18=0,"Break-even","Loss")) -> Profitable | X18: =IF(Q18="Cancelled","Not Applicable",IF(Q18="Processing","Pending",IF(B18="","Unknown",IF(Orders!J18="","Unknown",IF(Orders!J18<=3,"Fast",IF(Orders!J18<=6,"Standard","Slow")))))) -> Standard | Y18: =IF(OR(Q18="Cancelled",Q18="Returned"),0,O18) -> 1437.45
A19: =Orders!A19 -> O000018 | B19: =Orders!B19 -> 45673 | C19: =Orders!C19 -> C0209 | D19: =Orders!D19 -> P1050 | E19: =INDEX(Products!$B$2:$B$101,MATCH(D19,Products!$A$2:$A$101,0)) -> Hair Serum | F19: =INDEX(Products!$C$2:$C$101,MATCH(D19,Products!$A$2:$A$101,0)) -> Beauty | G19: =Orders!E19 -> 1 | H19: =INDEX(Products!$D$2:$D$101,MATCH(D19,Products!$A$2:$A$101,0)) -> 449 | I19: =INDEX(Products!$E$2:$E$101,MATCH(D19,Products!$A$2:$A$101,0)) -> 190 | J19: =Orders!F19 -> 0.1 | K19: =G19*H19 -> 449 | L19: =K19*J19 -> 44.9 | M19: =K19-L19 -> 404.1 | N19: =G19*I19 -> 190 | O19: =M19-N19 -> 214.1 | P19: =IFERROR(O19/M19,0) -> 0.52981935 | Q19: =Orders!H19 -> Delivered | R19: =INDEX(Customers!$C$2:$C$301,MATCH(C19,Customers!$A$2:$A$301,0)) -> Ahmedabad | S19: =INDEX(Customers!$E$2:$E$301,MATCH(C19,Customers!$A$2:$A$301,0)) -> Returning | T19: =Orders!I19 -> Website | U19: =IF(Q19="Delivered","Completed",IF(Q19="Cancelled","Cancelled",IF(Q19="Returned","Returned","In Progress"))) -> Completed | V19: =IF(M19>=10000,"High Value",IF(M19>=5000,"Medium Value","Low Value")) -> Low Value | W19: =IF(O19>0,"Profitable",IF(O19=0,"Break-even","Loss")) -> Profitable | X19: =IF(Q19="Cancelled","Not Applicable",IF(Q19="Processing","Pending",IF(B19="","Unknown",IF(Orders!J19="","Unknown",IF(Orders!J19<=3,"Fast",IF(Orders!J19<=6,"Standard","Slow")))))) -> Slow | Y19: =IF(OR(Q19="Cancelled",Q19="Returned"),0,O19) -> 214.1
A20: =Orders!A20 -> O000019 | B20: =Orders!B20 -> 45791 | C20: =Orders!C20 -> C0146 | D20: =Orders!D20 -> P1028 | E20: =INDEX(Products!$B$2:$B$101,MATCH(D20,Products!$A$2:$A$101,0)) -> Sneakers | F20: =INDEX(Products!$C$2:$C$101,MATCH(D20,Products!$A$2:$A$101,0)) -> Fashion | G20: =Orders!E20 -> 2 | H20: =INDEX(Products!$D$2:$D$101,MATCH(D20,Products!$A$2:$A$101,0)) -> 1799 | I20: =INDEX(Products!$E$2:$E$101,MATCH(D20,Products!$A$2:$A$101,0)) -> 950 | J20: =Orders!F20 -> 0.2 | K20: =G20*H20 -> 3598 | L20: =K20*J20 -> 719.6 | M20: =K20-L20 -> 2878.4 | N20: =G20*I20 -> 1900 | O20: =M20-N20 -> 978.4 | P20: =IFERROR(O20/M20,0) -> 0.33991106 | Q20: =Orders!H20 -> Returned | R20: =INDEX(Customers!$C$2:$C$301,MATCH(C20,Customers!$A$2:$A$301,0)) -> Kolkata | S20: =INDEX(Customers!$E$2:$E$301,MATCH(C20,Customers!$A$2:$A$301,0)) -> New | T20: =Orders!I20 -> Mobile App | U20: =IF(Q20="Delivered","Completed",IF(Q20="Cancelled","Cancelled",IF(Q20="Returned","Returned","In Progress"))) -> Returned | V20: =IF(M20>=10000,"High Value",IF(M20>=5000,"Medium Value","Low Value")) -> Low Value | W20: =IF(O20>0,"Profitable",IF(O20=0,"Break-even","Loss")) -> Profitable | X20: =IF(Q20="Cancelled","Not Applicable",IF(Q20="Processing","Pending",IF(B20="","Unknown",IF(Orders!J20="","Unknown",IF(Orders!J20<=3,"Fast",IF(Orders!J20<=6,"Standard","Slow")))))) -> Standard | Y20: =IF(OR(Q20="Cancelled",Q20="Returned"),0,O20) -> 0
A21: =Orders!A21 -> O000020 | B21: =Orders!B21 -> 45891 | C21: =Orders!C21 -> C0168 | D21: =Orders!D21 -> P1040 | E21: =INDEX(Products!$B$2:$B$101,MATCH(D21,Products!$A$2:$A$101,0)) -> Curtain Set | F21: =INDEX(Products!$C$2:$C$101,MATCH(D21,Products!$A$2:$A$101,0)) -> Home & Kitchen | G21: =Orders!E21 -> 1 | H21: =INDEX(Products!$D$2:$D$101,MATCH(D21,Products!$A$2:$A$101,0)) -> 1099 | I21: =INDEX(Products!$E$2:$E$101,MATCH(D21,Products!$A$2:$A$101,0)) -> 550 | J21: =Orders!F21 -> 0.2 | K21: =G21*H21 -> 1099 | L21: =K21*J21 -> 219.8 | M21: =K21-L21 -> 879.2 | N21: =G21*I21 -> 550 | O21: =M21-N21 -> 329.2 | P21: =IFERROR(O21/M21,0) -> 0.3744313 | Q21: =Orders!H21 -> Delivered | R21: =INDEX(Customers!$C$2:$C$301,MATCH(C21,Customers!$A$2:$A$301,0)) -> Jaipur | S21: =INDEX(Customers!$E$2:$E$301,MATCH(C21,Customers!$A$2:$A$301,0)) -> Returning | T21: =Orders!I21 -> Mobile App | U21: =IF(Q21="Delivered","Completed",IF(Q21="Cancelled","Cancelled",IF(Q21="Returned","Returned","In Progress"))) -> Completed | V21: =IF(M21>=10000,"High Value",IF(M21>=5000,"Medium Value","Low Value")) -> Low Value | W21: =IF(O21>0,"Profitable",IF(O21=0,"Break-even","Loss")) -> Profitable | X21: =IF(Q21="Cancelled","Not Applicable",IF(Q21="Processing","Pending",IF(B21="","Unknown",IF(Orders!J21="","Unknown",IF(Orders!J21<=3,"Fast",IF(Orders!J21<=6,"Standard","Slow")))))) -> Fast | Y21: =IF(OR(Q21="Cancelled",Q21="Returned"),0,O21) -> 329.2
A22: =Orders!A22 -> O000021 | B22: =Orders!B22 -> 45813 | C22: =Orders!C22 -> C0231 | D22: =Orders!D22 -> P1019 | E22: =INDEX(Products!$B$2:$B$101,MATCH(D22,Products!$A$2:$A$101,0)) -> Running Shoes | F22: =INDEX(Products!$C$2:$C$101,MATCH(D22,Products!$A$2:$A$101,0)) -> Fashion | G22: =Orders!E22 -> 5 | H22: =INDEX(Products!$D$2:$D$101,MATCH(D22,Products!$A$2:$A$101,0)) -> 1999 | I22: =INDEX(Products!$E$2:$E$101,MATCH(D22,Products!$A$2:$A$101,0)) -> 1100 | J22: =Orders!F22 -> 0.1 | K22: =G22*H22 -> 9995 | L22: =K22*J22 -> 999.5 | M22: =K22-L22 -> 8995.5 | N22: =G22*I22 -> 5500 | O22: =M22-N22 -> 3495.5 | P22: =IFERROR(O22/M22,0) -> 0.38858318 | Q22: =Orders!H22 -> Returned | R22: =INDEX(Customers!$C$2:$C$301,MATCH(C22,Customers!$A$2:$A$301,0)) -> Gurugram | S22: =INDEX(Customers!$E$2:$E$301,MATCH(C22,Customers!$A$2:$A$301,0)) -> New | T22: =Orders!I22 -> Mobile App | U22: =IF(Q22="Delivered","Completed",IF(Q22="Cancelled","Cancelled",IF(Q22="Returned","Returned","In Progress"))) -> Returned | V22: =IF(M22>=10000,"High Value",IF(M22>=5000,"Medium Value","Low Value")) -> Medium Value | W22: =IF(O22>0,"Profitable",IF(O22=0,"Break-even","Loss")) -> Profitable | X22: =IF(Q22="Cancelled","Not Applicable",IF(Q22="Processing","Pending",IF(B22="","Unknown",IF(Orders!J22="","Unknown",IF(Orders!J22<=3,"Fast",IF(Orders!J22<=6,"Standard","Slow")))))) -> Fast | Y22: =IF(OR(Q22="Cancelled",Q22="Returned"),0,O22) -> 0
A23: =Orders!A23 -> O000022 | B23: =Orders!B23 -> 45707 | C23: =Orders!C23 -> C0037 | D23: =Orders!D23 -> P1050 | E23: =INDEX(Products!$B$2:$B$101,MATCH(D23,Products!$A$2:$A$101,0)) -> Hair Serum | F23: =INDEX(Products!$C$2:$C$101,MATCH(D23,Products!$A$2:$A$101,0)) -> Beauty | G23: =Orders!E23 -> 2 | H23: =INDEX(Products!$D$2:$D$101,MATCH(D23,Products!$A$2:$A$101,0)) -> 449 | I23: =INDEX(Products!$E$2:$E$101,MATCH(D23,Products!$A$2:$A$101,0)) -> 190 | J23: =Orders!F23 -> 0 | K23: =G23*H23 -> 898 | L23: =K23*J23 -> 0 | M23: =K23-L23 -> 898 | N23: =G23*I23 -> 380 | O23: =M23-N23 -> 518 | P23: =IFERROR(O23/M23,0) -> 0.57683742 | Q23: =Orders!H23 -> Delivered | R23: =INDEX(Customers!$C$2:$C$301,MATCH(C23,Customers!$A$2:$A$301,0)) -> Surat | S23: =INDEX(Customers!$E$2:$E$301,MATCH(C23,Customers!$A$2:$A$301,0)) -> Returning | T23: =Orders!I23 -> Mobile App | U23: =IF(Q23="Delivered","Completed",IF(Q23="Cancelled","Cancelled",IF(Q23="Returned","Returned","In Progress"))) -> Completed | V23: =IF(M23>=10000,"High Value",IF(M23>=5000,"Medium Value","Low Value")) -> Low Value | W23: =IF(O23>0,"Profitable",IF(O23=0,"Break-even","Loss")) -> Profitable | X23: =IF(Q23="Cancelled","Not Applicable",IF(Q23="Processing","Pending",IF(B23="","Unknown",IF(Orders!J23="","Unknown",IF(Orders!J23<=3,"Fast",IF(Orders!J23<=6,"Standard","Slow")))))) -> Slow | Y23: =IF(OR(Q23="Cancelled",Q23="Returned"),0,O23) -> 518
A24: =Orders!A24 -> O000023 | B24: =Orders!B24 -> 45661 | C24: =Orders!C24 -> C0117 | D24: =Orders!D24 -> P1058 | E24: =INDEX(Products!$B$2:$B$101,MATCH(D24,Products!$A$2:$A$101,0)) -> Nail Care Kit | F24: =INDEX(Products!$C$2:$C$101,MATCH(D24,Products!$A$2:$A$101,0)) -> Beauty | G24: =Orders!E24 -> 2 | H24: =INDEX(Products!$D$2:$D$101,MATCH(D24,Products!$A$2:$A$101,0)) -> 399 | I24: =INDEX(Products!$E$2:$E$101,MATCH(D24,Products!$A$2:$A$101,0)) -> 170 | J24: =Orders!F24 -> 0.2 | K24: =G24*H24 -> 798 | L24: =K24*J24 -> 159.6 | M24: =K24-L24 -> 638.4 | N24: =G24*I24 -> 340 | O24: =M24-N24 -> 298.4 | P24: =IFERROR(O24/M24,0) -> 0.46741855 | Q24: =Orders!H24 -> Delivered | R24: =INDEX(Customers!$C$2:$C$301,MATCH(C24,Customers!$A$2:$A$301,0)) -> Surat | S24: =INDEX(Customers!$E$2:$E$301,MATCH(C24,Customers!$A$2:$A$301,0)) -> Returning | T24: =Orders!I24 -> Website | U24: =IF(Q24="Delivered","Completed",IF(Q24="Cancelled","Cancelled",IF(Q24="Returned","Returned","In Progress"))) -> Completed | V24: =IF(M24>=10000,"High Value",IF(M24>=5000,"Medium Value","Low Value")) -> Low Value | W24: =IF(O24>0,"Profitable",IF(O24=0,"Break-even","Loss")) -> Profitable | X24: =IF(Q24="Cancelled","Not Applicable",IF(Q24="Processing","Pending",IF(B24="","Unknown",IF(Orders!J24="","Unknown",IF(Orders!J24<=3,"Fast",IF(Orders!J24<=6,"Standard","Slow")))))) -> Standard | Y24: =IF(OR(Q24="Cancelled",Q24="Returned"),0,O24) -> 298.4
... A1501: =Orders!A1501 -> O001500 | B1501: =Orders!B1501 -> 45768 | C1501: =Orders!C1501 -> C0266 | D1501: =Orders!D1501 -> P1069 | E1501: =INDEX(Products!$B$2:$B$101,MATCH(D1501,Products!$A$2:$A$101,0)) -> Sports Duffel Bag | F1501: =INDEX(Products!$C$2:$C$101,MATCH(D1501,Products!$A$2:$A$101,0)) -> Sports & Outdoors | G1501: =Orders!E1501 -> 1 | H1501: =INDEX(Products!$D$2:$D$101,MATCH(D1501,Products!$A$2:$A$101,0)) -> 999 | I1501: =INDEX(Products!$E$2:$E$101,MATCH(D1501,Products!$A$2:$A$101,0)) -> 500 | J1501: =Orders!F1501 -> 0.2 | K1501: =G1501*H1501 -> 999 | L1501: =K1501*J1501 -> 199.8 | M1501: =K1501-L1501 -> 799.2 | N1501: =G1501*I1501 -> 500 | O1501: =M1501-N1501 -> 299.2 | P1501: =IFERROR(O1501/M1501,0) -> 0.37437437 | Q1501: =Orders!H1501 -> Shipped | R1501: =INDEX(Customers!$C$2:$C$301,MATCH(C1501,Customers!$A$2:$A$301,0)) -> Kolkata | S1501: =INDEX(Customers!$E$2:$E$301,MATCH(C1501,Customers!$A$2:$A$301,0)) -> Returning | T1501: =Orders!I1501 -> Mobile App | U1501: =IF(Q1501="Delivered","Completed",IF(Q1501="Cancelled","Cancelled",IF(Q1501="Returned","Returned","In Progress"))) -> In Progress | V1501: =IF(M1501>=10000,"High Value",IF(M1501>=5000,"Medium Value","Low Value")) -> Low Value | W1501: =IF(O1501>0,"Profitable",IF(O1501=0,"Break-even","Loss")) -> Profitable | X1501: =IF(Q1501="Cancelled","Not Applicable",IF(Q1501="Processing","Pending",IF(B1501="","Unknown",IF(Orders!J1501="","Unknown",IF(Orders!J1501<=3,"Fast",IF(Orders!J1501<=6,"Standard","Slow")))))) -> Standard | Y1501: =IF(OR(Q1501="Cancelled",Q1501="Returned"),0,O1501) -> 299.2

Sheet Pivot Analysis 
A1: Category | B1: Sum - Net Revenue | E1: Sales Channel | F1: Sum - Net Revenue | I1: Customer City | J1: Sum - Net Revenue
A2: Appliances | B2: 589663.3 | E2: Marketplace | F2: 727205.85 | I2: Ahmedabad | J2: 91684.65
A3: Beauty | B3: 168193.5 | E3: Mobile App | F3: 1084542.6 | I3: Bengaluru | J3: 118757.75
A4: Books & Stationery | B4: 133622.05 | E4: Website | F4: 523015.45 | I4: Bhopal | J4: 95776.4
A5: Electronics | B5: 460464.05 | E5: Total Result | F5: 2334764 | I5: Chandigarh | J5: 106637.45
A6: Fashion | B6: 427691.1 | I6: Chennai | J6: 141129.45
A7: Home & Kitchen | B7: 304282.9 | I7: Coimbatore | J7: 134728.5
A8: Sports & Outdoors | B8: 250847.05 | E8: Order Status | F8: Count - Order ID | I8: Delhi | J8: 105367.5
A9: Total Result | B9: 2334764 | E9: Cancelled | F9: 89 | I9: Gurugram | J9: 135453.35
E10: Delivered | F10: 1078 | I10: Hyderabad | J10: 134207.4
E11: Processing | F11: 99 | I11: Indore | J11: 125202.1
A12: Category | B12: Sum - Net Profit | E12: Returned | F12: 73 | I12: Jaipur | J12: 110543.55
A13: Appliances | B13: 152944.1 | E13: Shipped | F13: 161 | I13: Kochi | J13: 114936.25
A14: Beauty | B14: 71643.1 | E14: Total Result | F14: 1500 | I14: Kolkata | J14: 107890.85
A15: Books & Stationery | B15: 63022.75 | I15: Lucknow | J15: 130604.4
A16: Electronics | B16: 151043 | I16: Mumbai | J16: 105327.25
A17: Fashion | B17: 166824.65 | E17: Customer Segment | F17: Sum - Net Revenue | I17: Nagpur | J17: 124828.55
A18: Home & Kitchen | B18: 130803.85 | E18: New | F18: 825360.65 | I18: Noida | J18: 90450.25
A19: Sports & Outdoors | B19: 102658.3 | E19: Returning | F19: 1296792.5 | I19: Pune | J19: 124100
A20: Total Result | B20: 838939.75 | E20: VIP | F20: 212610.8 | I20: Surat | J20: 85437.25
E21: Total Result | F21: 2334764 | I21: Visakhapatnam | J21: 151701.05
I22: Total Result | J22: 2334764

Sheet Dashboard
B1: E-Commerce Sales Analysis Dashboard
B4: Total Orders | E4: Delivered Orders | H4: Delivered Revenue
B5: =Formula_Analysis!AB2 -> 1500 | E5: =Formula_Analysis!AB3 -> 1078 | H5: =Formula_Analysis!AB6 -> 1682287.2
B7: Delivered Profit | E7: Cancellation Rate | H7: Average Delivery Days
B8: =Formula_Analysis!AB7 -> 683645.25 | E8: =Formula_Analysis!AB4/Formula_Analysis!AB2 -> 0.059333333 | H8: =Formula_Analysis!AB11 -> 4.5686456
A69: KEY BUSINESS INSIGHTS
A71: 01- Revenue Leader: Appliances
A72: Appliances generated the highest category revenue of 589,663.30.
A73: Recommendation: Maintain availability of best-selling appliance products.
A75: 02- Profit Leader: Fashion
A76: Fashion generated the highest category profit of 166,824.65.
A77: Recommendation: Analyse pricing, costs, and discounts to protect margins.
A79: 03- Leading Sales Channel: Mobile App
A80: The mobile app recorded the highest channel revenue of 1,084,542.65.
A81: Recommendation: Improve app usability and encourage repeat purchases.
A83: 04- Returning Customers Lead
A84: Returning customers contributed the highest segment revenue of 1,296,792.50.
... A93: Recommendation: Monitor pending shipments and investigate cancellation and return reasons to improve fulfilment performance.
